<?xml version="1.0" encoding="utf-8"?>
<!-- This URDF was automatically created by SolidWorks to URDF Exporter! Originally created by Stephen Brawner (brawner@gmail.com) 
     Commit Version: 1.6.0-4-g7f85cfe  Build Version: 1.6.7995.38578
     For more information, please see http://wiki.ros.org/sw_urdf_exporter -->
<robot
  name="quadruped_robot">
  <link
    name="body">
    <inertial>
      <origin
        xyz="-1.46356337563103E-07 -3.51552600363902E-08 1.14116540661513E-08"
        rpy="0 0 0" />
      <mass
        value="79.5537197619101" />
      <inertia
        ixx="1.64089584946242"
        ixy="3.23528256055048E-06"
        ixz="-5.94676453127047E-07"
        iyy="6.25234462192461"
        iyz="-1.08488706514317E-07"
        izz="7.38765675032663" />
    </inertial>
    <visual>
      <origin
        xyz="0 0 0"
        rpy="0 0 0" />
      <geometry>
        <mesh
          filename="package://quadruped_robot/meshes/body.STL" />
      </geometry>
      <material
        name="">
        <color
          rgba="0 0.752941176470588 0 1" />
      </material>
    </visual>
    <collision>
      <origin
        xyz="0 0 0"
        rpy="0 0 0" />
      <geometry>
        <mesh
          filename="package://quadruped_robot/meshes/body.STL" />
      </geometry>
    </collision>
  </link>
  <link
    name="front_right_thigh">
    <inertial>
      <origin
        xyz="0.0631841605156611 -0.0140938845807083 0.0562244576815387"
        rpy="0 0 0" />
      <mass
        value="2.85003532279257" />
      <inertia
        ixx="0.0130181531074912"
        ixy="0.000348055845302443"
        ixz="-0.00138851689790659"
        iyy="0.0125988308050032"
        iyz="0.00142242382887273"
        izz="0.00728094257251726" />
    </inertial>
    <visual>
      <origin
        xyz="0 0 0"
        rpy="0 0 0" />
      <geometry>
        <mesh
          filename="package://quadruped_robot/meshes/front_right_thigh.STL" />
      </geometry>
      <material
        name="">
        <color
          rgba="0.250980392156863 0.250980392156863 0.250980392156863 1" />
      </material>
    </visual>
    <collision>
      <origin
        xyz="0 0 0"
        rpy="0 0 0" />
      <geometry>
        <mesh
          filename="package://quadruped_robot/meshes/front_right_thigh.STL" />
      </geometry>
    </collision>
  </link>
  <joint
    name="front_right_thigh_joint"
    type="revolute">
    <origin
      xyz="0.24988 -0.18 0"
      rpy="1.3364 0 0" />
    <parent
      link="body" />
    <child
      link="front_right_thigh" />
    <axis
      xyz="-1 0 0" />
    <limit
      lower="-3.142"
      upper="3.142"
      effort="0"
      velocity="0" />
  </joint>
  <link
    name="front_right_leg">
    <inertial>
      <origin
        xyz="0.0858075880091789 -0.274386624401192 -0.0220457366644032"
        rpy="0 0 0" />
      <mass
        value="6.9381686574405" />
      <inertia
        ixx="0.134972149319534"
        ixy="-0.0337211101903498"
        ixz="0.00607269451018088"
        iyy="0.030889997795707"
        iyz="0.020592041651515"
        izz="0.141529606841831" />
    </inertial>
    <visual>
      <origin
        xyz="0 0 0"
        rpy="0 0 0" />
      <geometry>
        <mesh
          filename="package://quadruped_robot/meshes/front_right_leg.STL" />
      </geometry>
      <material
        name="">
        <color
          rgba="0.501960784313725 1 0.501960784313725 1" />
      </material>
    </visual>
    <collision>
      <origin
        xyz="0 0 0"
        rpy="0 0 0" />
      <geometry>
        <mesh
          filename="package://quadruped_robot/meshes/front_right_leg.STL" />
      </geometry>
    </collision>
  </link>
  <joint
    name="front_right_leg_joint"
    type="revolute">
    <origin
      xyz="0 0 0"
      rpy="-2.9656 -1.5699 3.1416" />
    <parent
      link="front_right_thigh" />
    <child
      link="front_right_leg" />
    <axis
      xyz="0.96999 -0.23939 0.042598" />
    <limit
      lower="-3.14"
      upper="3.14"
      effort="0"
      velocity="0" />
  </joint>
  <link
    name="front_right_shin">
    <inertial>
      <origin
        xyz="0.00418914190493158 0.23566779303797 -0.0633269158639955"
        rpy="0 0 0" />
      <mass
        value="2.18909067780491" />
      <inertia
        ixx="0.0467383352046175"
        ixy="-0.00903914771720584"
        ixz="0.00667319774583945"
        iyy="0.020672751397194"
        iyz="0.0216040171949114"
        izz="0.0339991887478004" />
    </inertial>
    <visual>
      <origin
        xyz="0 0 0"
        rpy="0 0 0" />
      <geometry>
        <mesh
          filename="package://quadruped_robot/meshes/front_right_shin.STL" />
      </geometry>
      <material
        name="">
        <color
          rgba="0 0 0 1" />
      </material>
    </visual>
    <collision>
      <origin
        xyz="0 0 0"
        rpy="0 0 0" />
      <geometry>
        <mesh
          filename="package://quadruped_robot/meshes/front_right_shin.STL" />
      </geometry>
    </collision>
  </link>
  <joint
    name="front_right_shin_joint"
    type="revolute">
    <origin
      xyz="-0.02707 -0.5123 -0.069163"
      rpy="0.79708 0 -3.1416" />
    <parent
      link="front_right_leg" />
    <child
      link="front_right_shin" />
    <axis
      xyz="-0.96999 0.19775 -0.14147" />
    <limit
      lower="-3.14"
      upper="3.14"
      effort="0"
      velocity="0" />
  </joint>
  <link
    name="front_left_thigh">
    <inertial>
      <origin
        xyz="0.063184161475395 -0.00512856543969809 0.0577366868658614"
        rpy="0 0 0" />
      <mass
        value="2.8500353343221" />
      <inertia
        ixx="0.0130181530639505"
        ixy="0.000126648746459907"
        ixz="-0.00142586185017246"
        iyy="0.0129081788411086"
        iyz="0.000531521185502727"
        izz="0.00697159449339958" />
    </inertial>
    <visual>
      <origin
        xyz="0 0 0"
        rpy="0 0 0" />
      <geometry>
        <mesh
          filename="package://quadruped_robot/meshes/front_left_thigh.STL" />
      </geometry>
      <material
        name="">
        <color
          rgba="0.250980392156863 0.250980392156863 0.250980392156863 1" />
      </material>
    </visual>
    <collision>
      <origin
        xyz="0 0 0"
        rpy="0 0 0" />
      <geometry>
        <mesh
          filename="package://quadruped_robot/meshes/front_left_thigh.STL" />
      </geometry>
    </collision>
  </link>
  <joint
    name="front_left_thigh_joint"
    type="revolute">
    <origin
      xyz="0.249882405181029 0.18 0"
      rpy="-1.64194996163522 0 0" />
    <parent
      link="body" />
    <child
      link="front_left_thigh" />
    <axis
      xyz="-1 0 0" />
    <limit
      lower="-3.14"
      upper="3.14"
      effort="0"
      velocity="0" />
  </joint>
  <link
    name="front_left_leg">
    <inertial>
      <origin
        xyz="0.136969074450681 -0.190796822136722 -0.116184197817902"
        rpy="0 0 0" />
      <mass
        value="6.93816849077714" />
      <inertia
        ixx="0.144608795065026"
        ixy="0.00556110077343386"
        ixz="0.00338551617403583"
        iyy="0.0520734369969958"
        iyz="-0.0567169675239779"
        izz="0.110709512173605" />
    </inertial>
    <visual>
      <origin
        xyz="0 0 0"
        rpy="0 0 0" />
      <geometry>
        <mesh
          filename="package://quadruped_robot/meshes/front_left_leg.STL" />
      </geometry>
      <material
        name="">
        <color
          rgba="0.501960784313725 1 0.501960784313725 1" />
      </material>
    </visual>
    <collision>
      <origin
        xyz="0 0 0"
        rpy="0 0 0" />
      <geometry>
        <mesh
          filename="package://quadruped_robot/meshes/front_left_leg.STL" />
      </geometry>
    </collision>
  </link>
  <joint
    name="front_left_leg_joint"
    type="revolute">
    <origin
      xyz="0.070219 0 0.0315"
      rpy="-0.54504 -1.5699 -3.1416" />
    <parent
      link="front_left_thigh" />
    <child
      link="front_left_leg" />
    <axis
      xyz="0.99608 0.075661 0.045868" />
    <limit
      lower="-3.14"
      upper="3.14"
      effort="0"
      velocity="0" />
  </joint>
  <link
    name="front_left_shin">
    <inertial>
      <origin
        xyz="-0.147003063307667 0.311100364863869 0.19908214791875"
        rpy="0 0 0" />
      <mass
        value="2.18909081108663" />
      <inertia
        ixx="0.0491815057728991"
        ixy="0.000910327003178677"
        ixz="0.00409887323092259"
        iyy="0.0477028312815452"
        iyz="-0.0100895709041585"
        izz="0.0045259428443968" />
    </inertial>
    <visual>
      <origin
        xyz="0 0 0"
        rpy="0 0 0" />
      <geometry>
        <mesh
          filename="package://quadruped_robot/meshes/front_left_shin.STL" />
      </geometry>
      <material
        name="">
        <color
          rgba="0 0 0 1" />
      </material>
    </visual>
    <collision>
      <origin
        xyz="0 0 0"
        rpy="0 0 0" />
      <geometry>
        <mesh
          filename="package://quadruped_robot/meshes/front_left_shin.STL" />
      </geometry>
    </collision>
  </link>
  <joint
    name="front_left_shin_joint"
    type="revolute">
    <origin
      xyz="0.028460525371978 -0.5 0"
      rpy="-1.89034893239217 0 3.14159265358979" />
    <parent
      link="front_left_leg" />
    <child
      link="front_left_shin" />
    <axis
      xyz="-0.996078094500597 -0.0197781632448234 -0.0862395148103312" />
    <limit
      lower="-3.14"
      upper="3.14"
      effort="0"
      velocity="0" />
  </joint>
  <link
    name="back_right_thigh">
    <inertial>
      <origin
        xyz="0.0631841598357021 0.0203660978690759 0.0542683084618216"
        rpy="0 0 0" />
      <mass
        value="2.85003531462536" />
      <inertia
        ixx="0.0130181531384223"
        ixy="-0.000502965372963859"
        ixz="-0.00134020445069207"
        iyy="0.0122108504715142"
        iyz="-0.0019839347377104"
        izz="0.00766892293626462" />
    </inertial>
    <visual>
      <origin
        xyz="0 0 0"
        rpy="0 0 0" />
      <geometry>
        <mesh
          filename="package://quadruped_robot/meshes/back_right_thigh.STL" />
      </geometry>
      <material
        name="">
        <color
          rgba="0.250980392156863 0.250980392156863 0.250980392156863 1" />
      </material>
    </visual>
    <collision>
      <origin
        xyz="0 0 0"
        rpy="0 0 0" />
      <geometry>
        <mesh
          filename="package://quadruped_robot/meshes/back_right_thigh.STL" />
      </geometry>
    </collision>
  </link>
  <joint
    name="back_right_thigh_joint"
    type="revolute">
    <origin
      xyz="-0.249882405181029 -0.18 0"
      rpy="-1.2050955352319 0 3.14159265358979" />
    <parent
      link="body" />
    <child
      link="back_right_thigh" />
    <axis
      xyz="-1 0 0" />
    <limit
      lower="-3.14"
      upper="3.14"
      effort="0"
      velocity="0" />
  </joint>
  <link
    name="back_right_leg">
    <inertial>
      <origin
        xyz="0.180550581891122 -0.226034533866513 -0.155393066583193"
        rpy="0 0 0" />
      <mass
        value="6.93816860410077" />
      <inertia
        ixx="0.125886482107115"
        ixy="-0.0374979912734983"
        ixz="-0.0257815829989208"
        iyy="0.0712450069693681"
        iyz="-0.0508733067288939"
        izz="0.11026026024829" />
    </inertial>
    <visual>
      <origin
        xyz="0 0 0"
        rpy="0 0 0" />
      <geometry>
        <mesh
          filename="package://quadruped_robot/meshes/back_right_leg.STL" />
      </geometry>
      <material
        name="">
        <color
          rgba="0.501960784313725 1 0.501960784313725 1" />
      </material>
    </visual>
    <collision>
      <origin
        xyz="0 0 0"
        rpy="0 0 0" />
      <geometry>
        <mesh
          filename="package://quadruped_robot/meshes/back_right_leg.STL" />
      </geometry>
    </collision>
  </link>
  <joint
    name="back_right_leg_joint"
    type="revolute">
    <origin
      xyz="0.070365 0 -0.12536"
      rpy="-0.60192 -1.5699 -3.1416" />
    <parent
      link="back_right_thigh" />
    <child
      link="back_right_leg" />
    <axis
      xyz="0.93624 -0.28957 -0.199" />
    <limit
      lower="-3.14"
      upper="3.14"
      effort="0"
      velocity="0" />
  </joint>
  <link
    name="back_right_shin">
    <inertial>
      <origin
        xyz="-0.0283079043897123 0.396345744991786 0.111537059182777"
        rpy="0 0 0" />
      <mass
        value="2.18909068675098" />
      <inertia
        ixx="0.0436733373732954"
        ixy="0.0138428755756602"
        ixz="-0.00734715609615314"
        iyy="0.0170538588260163"
        iyz="0.0174528345983278"
        izz="0.0406830797923565" />
    </inertial>
    <visual>
      <origin
        xyz="0 0 0"
        rpy="0 0 0" />
      <geometry>
        <mesh
          filename="package://quadruped_robot/meshes/back_right_shin.STL" />
      </geometry>
      <material
        name="">
        <color
          rgba="0 0 0 1" />
      </material>
    </visual>
    <collision>
      <origin
        xyz="0 0 0"
        rpy="0 0 0" />
      <geometry>
        <mesh
          filename="package://quadruped_robot/meshes/back_right_shin.STL" />
      </geometry>
    </collision>
  </link>
  <joint
    name="back_right_shin_joint"
    type="revolute">
    <origin
      xyz="0.041106 -0.5 0"
      rpy="-2.0613 0 0" />
    <parent
      link="back_right_leg" />
    <child
      link="back_right_shin" />
    <axis
      xyz="-0.93624 -0.31194 0.16169" />
    <limit
      lower="-3.14"
      upper="3.14"
      effort="0"
      velocity="0" />
  </joint>
  <link
    name="back_left_thigh">
    <inertial>
      <origin
        xyz="0.0631841616572668 -0.0109554744949077 0.0569192829063254"
        rpy="0 0 0" />
      <mass
        value="2.8500353369203" />
      <inertia
        ixx="0.013018153344184"
        ixy="0.000270563053479321"
        ixz="-0.00140567375050099"
        iyy="0.012739947525615"
        iyz="0.00111934520870139"
        izz="0.00713982598282035" />
    </inertial>
    <visual>
      <origin
        xyz="0 0 0"
        rpy="0 0 0" />
      <geometry>
        <mesh
          filename="package://quadruped_robot/meshes/back_left_thigh.STL" />
      </geometry>
      <material
        name="">
        <color
          rgba="0.250980392156863 0.250980392156863 0.250980392156863 1" />
      </material>
    </visual>
    <collision>
      <origin
        xyz="0 0 0"
        rpy="0 0 0" />
      <geometry>
        <mesh
          filename="package://quadruped_robot/meshes/back_left_thigh.STL" />
      </geometry>
    </collision>
  </link>
  <joint
    name="back_left_thigh_joint"
    type="revolute">
    <origin
      xyz="-0.249882405181029 0.18 0"
      rpy="1.36200189468701 0 3.14159265358979" />
    <parent
      link="body" />
    <child
      link="back_left_thigh" />
    <axis
      xyz="-1 0 0" />
    <limit
      lower="-3.14"
      upper="3.14"
      effort="0"
      velocity="0" />
  </joint>
  <link
    name="back_left_leg">
    <inertial>
      <origin
        xyz="0.0194306734672526 -0.259701123554023 -0.0271757080780708"
        rpy="0 0 0" />
      <mass
        value="6.93816847911244" />
      <inertia
        ixx="0.13843403763036"
        ixy="-0.0279314764539319"
        ixz="-0.00294621941506812"
        iyy="0.0250565740252852"
        iyz="-0.012674791437667"
        izz="0.143901132066975" />
    </inertial>
    <visual>
      <origin
        xyz="0 0 0"
        rpy="0 0 0" />
      <geometry>
        <mesh
          filename="package://quadruped_robot/meshes/back_left_leg.STL" />
      </geometry>
      <material
        name="">
        <color
          rgba="0.501960784313725 1 0.501960784313725 1" />
      </material>
    </visual>
    <collision>
      <origin
        xyz="0 0 0"
        rpy="0 0 0" />
      <geometry>
        <mesh
          filename="package://quadruped_robot/meshes/back_left_leg.STL" />
      </geometry>
    </collision>
  </link>
  <joint
    name="back_left_leg_joint"
    type="revolute">
    <origin
      xyz="0.0701724686163078 0 0.0810726777394658"
      rpy="3.04358892179118 -1.56986563009081 -3.14159265358249" />
    <parent
      link="back_left_thigh" />
    <child
      link="back_left_leg" />
    <axis
      xyz="0.98197618745736 -0.188099372550818 -0.0184768317818711" />
    <limit
      lower="-3.14"
      upper="3.14"
      effort="0"
      velocity="0" />
  </joint>
  <link
    name="back_left_shin">
    <inertial>
      <origin
        xyz="-0.0722642497205996 0.18652636979793 0.134149204221555"
        rpy="0 0 0" />
      <mass
        value="2.1890918917642" />
      <inertia
        ixx="0.0478525423423424"
        ixy="0.008167208903878"
        ixz="0.0033889293989778"
        iyy="0.0104195575101628"
        iyz="-0.0164013864415941"
        izz="0.0431381999151762" />
    </inertial>
    <visual>
      <origin
        xyz="0 0 0"
        rpy="0 0 0" />
      <geometry>
        <mesh
          filename="package://quadruped_robot/meshes/back_left_shin.STL" />
      </geometry>
      <material
        name="">
        <color
          rgba="0 0 0 1" />
      </material>
    </visual>
    <collision>
      <origin
        xyz="0 0 0"
        rpy="0 0 0" />
      <geometry>
        <mesh
          filename="package://quadruped_robot/meshes/back_left_shin.STL" />
      </geometry>
    </collision>
  </link>
  <joint
    name="back_left_shin_joint"
    type="revolute">
    <origin
      xyz="0 -0.5 0"
      rpy="2.84405277747574 0 0" />
    <parent
      link="back_left_leg" />
    <child
      link="back_left_shin" />
    <axis
      xyz="-0.98197618745736 -0.174417566004741 -0.0728098889965498" />
    <limit
      lower="-3.14"
      upper="3.14"
      effort="0"
      velocity="0" />
  </joint>
</robot>